<?xml version="1.0" ?>
<!-- =================================================================================== -->
<!-- |    This document was autogenerated by xacro from /home/diego/rr_ros_ws/src/horu_sim/urdf/horu.urdf.xacro | -->
<!-- |    EDITING THIS FILE BY HAND IS NOT RECOMMENDED                                 | -->
<!-- =================================================================================== -->
<!-- TO-DO -->
<!-- change sizes -->
<!-- change inertia -->
<robot name="horu">
  <!-- SIZES -->
  <!-- INERTIA -->
  <!-- LINKS -->
  <link name="dummy_link">
    </link>
  <link name="base_link">
    <visual>
      <geometry>
        <box size="1.0 0.6 0.4"/>
      </geometry>
    </visual>
    <collision>
      <geometry>
        <box size="1.0 0.6 0.4"/>
      </geometry>
    </collision>
    <inertial>
      <mass value="1.0"/>
      <origin xyz="0 0 0"/>
      <inertia ixx="0.083" ixy="0.0" ixz="0.0" iyy="0.021" iyz="0.0" izz="0.1"/>
    </inertial>
  </link>
  <link name="front_left_axle_link">
    </link>
  <link name="front_right_axle_link">
    </link>
  <!-- JOINTS -->
  <joint name="dummy_joint" type="fixed">
    <parent link="dummy_link"/>
    <child link="base_link"/>
    <origin rpy="0 0 0" xyz="0 0 0"/>
  </joint>
  <joint name="front_left_axle_joint" type="continuous">
    <parent link="base_link"/>
    <child link="front_left_axle_link"/>
    <origin rpy="0 0 0" xyz="0.3 0.325 -0.15"/>
    <axis xyz="0 1 0"/>
  </joint>
  <joint name="front_right_axle_joint" type="continuous">
    <parent link="base_link"/>
    <child link="front_right_axle_link"/>
    <origin rpy="0 0 0" xyz="0.3 -0.325 -0.15"/>
    <axis xyz="0 1 0"/>
  </joint>
</robot>
<!-- 
EJECUTAR ESTA LINEA ANTES DE HACER catkin_make

rosrun xacro xacro ~/catkin_ws/src/horu_sim/urdf/horu.urdf.xacro > ~/catkin_ws/src/horu_sim/urdf/horu.urdf

check_urdf ~/catkin_ws/src/horu_sim/urdf/horu.urdf

-->

